Workbook

Sheet Analysis
A1: Scenario A: 2x 10MVAR, 1x 50MVAR | O1: Scenario B: 1x 100 MVAR | Z1: Scenario C: 3x 10 MVAR
A3: Bus 4 | B3: Bus 9 | C3: Bus 14 | O3: Bus 4 | P3: Bus 9 | Q3: Bus 14 | Z3: Bus 4 | AA3: Bus 9 | AB3: Bus 14
A4: 52.632 | B4: 10.526 | C4: 10.526 | O4: 105.263 | P4: 0 | Q4: 0 | Z4: 10.526 | AA4: 10.526 | AB4: 10.526
A6: % Reduction in Load MW | O6: % Reduction in Load MW | Z6: % Reduction in Load MW
A7: hour | B7: Moderately Sunny | E7: Very Sunny | H7: Cloudy | K7: Average | O7: hour | P7: Very Sunny | S7: Cloudy | V7: Average | Z7: hour | AA7: Very Sunny | AD7: Cloudy | AG7: Average
B8: Load 4 | C8: Load 9 | D8: Load 14 | E8: Load 4 | F8: Load 9 | G8: Load 14 | H8: Load 4 | I8: Load 9 | J8: Load 14 | K8: Load 4 | L8: Load 9 | M8: Load 14 | P8: Load 4 | Q8: Load 9 | R8: Load 14 | S8: Load 4 | T8: Load 9 | U8: Load 14 | V8: Load 4 | W8: Load 9 | X8: Load 14 | AA8: Load 4 | AB8: Load 9 | AC8: Load 14 | AD8: Load 4 | AE8: Load 9 | AF8: Load 14 | AG8: Load 4 | AH8: Load 9 | AI8: Load 14 | AJ8: Avg of all | AK8: Sum
A9: 1 | B9: =-'Moderate sunny two 10 one 50'!AI2 -> 0.029615491 | C9: =-'Moderate sunny two 10 one 50'!AJ2 -> 0.027708266 | D9: =-'Moderate sunny two 10 one 50'!AK2 -> 0.035293576 | E9: =-'Very sunny two 10 one 50'!AI2 -> 0.029615491 | F9: =-'Very sunny two 10 one 50'!AJ2 -> 0.027708266 | G9: =-'Very sunny two 10 one 50'!AK2 -> 0.035293576 | H9: =-'cloudy two 10 one 50'!AI2 -> 0.029615491 | I9: =-'cloudy two 10 one 50'!AJ2 -> 0.027708266 | J9: =-'cloudy two 10 one 50'!AK2 -> 0.035293576 | K9: =AVERAGE(B9,E9,H9) -> 0.029615491 | L9: =AVERAGE(C9,F9,I9) -> 0.027708266 | M9: =AVERAGE(D9,G9,J9) -> 0.035293576 | O9: 1 | P9: =-'very sunny one 100'!AI2 -> 0.047015567 | Q9: =-'very sunny one 100'!AJ2 -> 0.018307269 | R9: =-'very sunny one 100'!AK2 -> 0.011415965 | S9: =-'cloudy one 100'!AI2 -> 0.047015567 | T9: =-'cloudy one 100'!AJ2 -> 0.018307269 | U9: =-'cloudy one 100'!AK2 -> 0.011415965 | V9: =AVERAGE(P9,S9) -> 0.047015567 | W9: =AVERAGE(Q9,T9) -> 0.018307269 | X9: =AVERAGE(R9,U9) -> 0.011415965 | Z9: 1 | AA9: =-'very sunny all 10'!AI2 -> 0.010567904 | AB9: =-'very sunny all 10'!AJ2 -> 0.019705801 | AC9: =-'very sunny all 10'!AK2 -> 0.030217224 | AD9: =-'cloudy all 10'!AI2 -> 0.010567904 | AE9: =-'cloudy all 10'!AJ2 -> 0.019705801 | AF9: =-'cloudy all 10'!AK2 -> 0.030217224 | AG9: =AVERAGE(AA9,AD9) -> 0.010567904 | AH9: =AVERAGE(AB9,AE9) -> 0.019705801 | AI9: =AVERAGE(AC9,AF9) -> 0.030217224 | AJ9: =AVERAGE(AG9:AI9) -> 0.020163643 | AK9: =SUM(AG9:AI9) -> 0.060490928
A10: 2 | B10: =-'Moderate sunny two 10 one 50'!AI3 -> 0.029585959 | C10: =-'Moderate sunny two 10 one 50'!AJ3 -> 0.027696407 | D10: =-'Moderate sunny two 10 one 50'!AK3 -> 0.035266434 | E10: =-'Very sunny two 10 one 50'!AI3 -> 0.029585959 | F10: =-'Very sunny two 10 one 50'!AJ3 -> 0.027696407 | G10: =-'Very sunny two 10 one 50'!AK3 -> 0.035266434 | H10: =-'cloudy two 10 one 50'!AI3 -> 0.029585959 | I10: =-'cloudy two 10 one 50'!AJ3 -> 0.027696407 | J10: =-'cloudy two 10 one 50'!AK3 -> 0.035266434 | K10: =AVERAGE(B10,E10,H10) -> 0.029585959 | L10: =AVERAGE(C10,F10,I10) -> 0.027696407 | M10: =AVERAGE(D10,G10,J10) -> 0.035266434 | O10: 2 | P10: =-'very sunny one 100'!AI3 -> 0.047690113 | Q10: =-'very sunny one 100'!AJ3 -> 0.018610608 | R10: =-'very sunny one 100'!AK3 -> 0.011622138 | S10: =-'cloudy one 100'!AI3 -> 0.047690113 | T10: =-'cloudy one 100'!AJ3 -> 0.018610608 | U10: =-'cloudy one 100'!AK3 -> 0.011622138 | V10: =AVERAGE(P10,S10) -> 0.047690113 | W10: =AVERAGE(Q10,T10) -> 0.018610608 | X10: =AVERAGE(R10,U10) -> 0.011622138 | Z10: 2 | AA10: =-'very sunny all 10'!AI3 -> 0.010553272 | AB10: =-'very sunny all 10'!AJ3 -> 0.019695317 | AC10: =-'very sunny all 10'!AK3 -> 0.030187161 | AD10: =-'cloudy all 10'!AI3 -> 0.010553272 | AE10: =-'cloudy all 10'!AJ3 -> 0.019695317 | AF10: =-'cloudy all 10'!AK3 -> 0.030187161 | AG10: =AVERAGE(AA10,AD10) -> 0.010553272 | AH10: =AVERAGE(AB10,AE10) -> 0.019695317 | AI10: =AVERAGE(AC10,AF10) -> 0.030187161 | AJ10: =AVERAGE(AG10:AI10) -> 0.02014525 | AK10: =SUM(AG10:AI10) -> 0.060435749
A11: 3 | B11: =-'Moderate sunny two 10 one 50'!AI4 -> 0.029471534 | C11: =-'Moderate sunny two 10 one 50'!AJ4 -> 0.027649534 | D11: =-'Moderate sunny two 10 one 50'!AK4 -> 0.035226505 | E11: =-'Very sunny two 10 one 50'!AI4 -> 0.029471534 | F11: =-'Very sunny two 10 one 50'!AJ4 -> 0.027649534 | G11: =-'Very sunny two 10 one 50'!AK4 -> 0.035226505 | H11: =-'cloudy two 10 one 50'!AI4 -> 0.029471534 | I11: =-'cloudy two 10 one 50'!AJ4 -> 0.027649534 | J11: =-'cloudy two 10 one 50'!AK4 -> 0.035226505 | K11: =AVERAGE(B11,E11,H11) -> 0.029471534 | L11: =AVERAGE(C11,F11,I11) -> 0.027649534 | M11: =AVERAGE(D11,G11,J11) -> 0.035226505 | O11: 3 | P11: =-'very sunny one 100'!AI4 -> 0.047959403 | Q11: =-'very sunny one 100'!AJ4 -> 0.018729082 | R11: =-'very sunny one 100'!AK4 -> 0.011698991 | S11: =-'cloudy one 100'!AI4 -> 0.047959403 | T11: =-'cloudy one 100'!AJ4 -> 0.018729082 | U11: =-'cloudy one 100'!AK4 -> 0.011698991 | V11: =AVERAGE(P11,S11) -> 0.047959403 | W11: =AVERAGE(Q11,T11) -> 0.018729082 | X11: =AVERAGE(R11,U11) -> 0.011698991 | Z11: 3 | AA11: =-'very sunny all 10'!AI4 -> 0.010446672 | AB11: =-'very sunny all 10'!AJ4 -> 0.019649819 | AC11: =-'very sunny all 10'!AK4 -> 0.030147584 | AD11: =-'cloudy all 10'!AI4 -> 0.010446672 | AE11: =-'cloudy all 10'!AJ4 -> 0.019649819 | AF11: =-'cloudy all 10'!AK4 -> 0.030147584 | AG11: =AVERAGE(AA11,AD11) -> 0.010446672 | AH11: =AVERAGE(AB11,AE11) -> 0.019649819 | AI11: =AVERAGE(AC11,AF11) -> 0.030147584 | AJ11: =AVERAGE(AG11:AI11) -> 0.020081358 | AK11: =SUM(AG11:AI11) -> 0.060244075
A12: 4 | B12: =-'Moderate sunny two 10 one 50'!AI5 -> 0.029462297 | C12: =-'Moderate sunny two 10 one 50'!AJ5 -> 0.027645678 | D12: =-'Moderate sunny two 10 one 50'!AK5 -> 0.035223335 | E12: =-'Very sunny two 10 one 50'!AI5 -> 0.029462297 | F12: =-'Very sunny two 10 one 50'!AJ5 -> 0.027645678 | G12: =-'Very sunny two 10 one 50'!AK5 -> 0.035223335 | H12: =-'cloudy two 10 one 50'!AI5 -> 0.029462297 | I12: =-'cloudy two 10 one 50'!AJ5 -> 0.027645678 | J12: =-'cloudy two 10 one 50'!AK5 -> 0.035223335 | K12: =AVERAGE(B12,E12,H12) -> 0.029462297 | L12: =AVERAGE(C12,F12,I12) -> 0.027645678 | M12: =AVERAGE(D12,G12,J12) -> 0.035223335 | O12: 4 | P12: =-'very sunny one 100'!AI5 -> 0.047981289 | Q12: =-'very sunny one 100'!AJ5 -> 0.018738758 | R12: =-'very sunny one 100'!AK5 -> 0.011705351 | S12: =-'cloudy one 100'!AI5 -> 0.047981289 | T12: =-'cloudy one 100'!AJ5 -> 0.018738758 | U12: =-'cloudy one 100'!AK5 -> 0.011705351 | V12: =AVERAGE(P12,S12) -> 0.047981289 | W12: =AVERAGE(Q12,T12) -> 0.018738758 | X12: =AVERAGE(R12,U12) -> 0.011705351 | Z12: 4 | AA12: =-'very sunny all 10'!AI5 -> 0.010437699 | AB12: =-'very sunny all 10'!AJ5 -> 0.019646107 | AC12: =-'very sunny all 10'!AK5 -> 0.030144204 | AD12: =-'cloudy all 10'!AI5 -> 0.010437699 | AE12: =-'cloudy all 10'!AJ5 -> 0.019646107 | AF12: =-'cloudy all 10'!AK5 -> 0.030144204 | AG12: =AVERAGE(AA12,AD12) -> 0.010437699 | AH12: =AVERAGE(AB12,AE12) -> 0.019646107 | AI12: =AVERAGE(AC12,AF12) -> 0.030144204 | AJ12: =AVERAGE(AG12:AI12) -> 0.020076003 | AK12: =SUM(AG12:AI12) -> 0.06022801
A13: 5 | B13: =-'Moderate sunny two 10 one 50'!AI6 -> 0.029604917 | C13: =-'Moderate sunny two 10 one 50'!AJ6 -> 0.02770423 | D13: =-'Moderate sunny two 10 one 50'!AK6 -> 0.035275608 | E13: =-'Very sunny two 10 one 50'!AI6 -> 0.029604917 | F13: =-'Very sunny two 10 one 50'!AJ6 -> 0.02770423 | G13: =-'Very sunny two 10 one 50'!AK6 -> 0.035275608 | H13: =-'cloudy two 10 one 50'!AI6 -> 0.029604917 | I13: =-'cloudy two 10 one 50'!AJ6 -> 0.02770423 | J13: =-'cloudy two 10 one 50'!AK6 -> 0.035275608 | K13: =AVERAGE(B13,E13,H13) -> 0.029604917 | L13: =AVERAGE(C13,F13,I13) -> 0.02770423 | M13: =AVERAGE(D13,G13,J13) -> 0.035275608 | O13: 5 | P13: =-'very sunny one 100'!AI6 -> 0.047547464 | Q13: =-'very sunny one 100'!AJ6 -> 0.018548536 | R13: =-'very sunny one 100'!AK6 -> 0.011581746 | S13: =-'cloudy one 100'!AI6 -> 0.047547464 | T13: =-'cloudy one 100'!AJ6 -> 0.018548536 | U13: =-'cloudy one 100'!AK6 -> 0.011581746 | V13: =AVERAGE(P13,S13) -> 0.047547464 | W13: =AVERAGE(Q13,T13) -> 0.018548536 | X13: =AVERAGE(R13,U13) -> 0.011581746 | Z13: 5 | AA13: =-'very sunny all 10'!AI6 -> 0.010568542 | AB13: =-'very sunny all 10'!AJ6 -> 0.019702135 | AC13: =-'very sunny all 10'!AK6 -> 0.030196085 | AD13: =-'cloudy all 10'!AI6 -> 0.010568542 | AE13: =-'cloudy all 10'!AJ6 -> 0.019702135 | AF13: =-'cloudy all 10'!AK6 -> 0.030196085 | AG13: =AVERAGE(AA13,AD13) -> 0.010568542 | AH13: =AVERAGE(AB13,AE13) -> 0.019702135 | AI13: =AVERAGE(AC13,AF13) -> 0.030196085 | AJ13: =AVERAGE(AG13:AI13) -> 0.020155587 | AK13: =SUM(AG13:AI13) -> 0.060466762
A14: 6 | B14: =-'Moderate sunny two 10 one 50'!AI7 -> 0.029632919 | C14: =-'Moderate sunny two 10 one 50'!AJ7 -> 0.027713944 | D14: =-'Moderate sunny two 10 one 50'!AK7 -> 0.035322962 | E14: =-'Very sunny two 10 one 50'!AI7 -> 0.029632919 | F14: =-'Very sunny two 10 one 50'!AJ7 -> 0.027713944 | G14: =-'Very sunny two 10 one 50'!AK7 -> 0.035322962 | H14: =-'cloudy two 10 one 50'!AI7 -> 0.029632919 | I14: =-'cloudy two 10 one 50'!AJ7 -> 0.027713944 | J14: =-'cloudy two 10 one 50'!AK7 -> 0.035322962 | K14: =AVERAGE(B14,E14,H14) -> 0.029632919 | L14: =AVERAGE(C14,F14,I14) -> 0.027713944 | M14: =AVERAGE(D14,G14,J14) -> 0.035322962 | O14: 6 | P14: =-'very sunny one 100'!AI7 -> 0.046063474 | Q14: =-'very sunny one 100'!AJ7 -> 0.01791355 | R14: =-'very sunny one 100'!AK7 -> 0.011186366 | S14: =-'cloudy one 100'!AI7 -> 0.046063474 | T14: =-'cloudy one 100'!AJ7 -> 0.01791355 | U14: =-'cloudy one 100'!AK7 -> 0.011186366 | V14: =AVERAGE(P14,S14) -> 0.046063474 | W14: =AVERAGE(Q14,T14) -> 0.01791355 | X14: =AVERAGE(R14,U14) -> 0.011186366 | Z14: 6 | AA14: =-'very sunny all 10'!AI7 -> 0.010561272 | AB14: =-'very sunny all 10'!AJ7 -> 0.019707981 | AC14: =-'very sunny all 10'!AK7 -> 0.030248327 | AD14: =-'cloudy all 10'!AI7 -> 0.010561272 | AE14: =-'cloudy all 10'!AJ7 -> 0.019707981 | AF14: =-'cloudy all 10'!AK7 -> 0.030248327 | AG14: =AVERAGE(AA14,AD14) -> 0.010561272 | AH14: =AVERAGE(AB14,AE14) -> 0.019707981 | AI14: =AVERAGE(AC14,AF14) -> 0.030248327 | AJ14: =AVERAGE(AG14:AI14) -> 0.020172527 | AK14: =SUM(AG14:AI14) -> 0.06051758
A15: 7 | B15: =-'Moderate sunny two 10 one 50'!AI8 -> 0.030708326 | C15: =-'Moderate sunny two 10 one 50'!AJ8 -> 0.028166838 | D15: =-'Moderate sunny two 10 one 50'!AK8 -> 0.035673171 | E15: =-'Very sunny two 10 one 50'!AI8 -> 0.030638568 | F15: =-'Very sunny two 10 one 50'!AJ8 -> 0.028103202 | G15: =-'Very sunny two 10 one 50'!AK8 -> 0.035596003 | H15: =-'cloudy two 10 one 50'!AI8 -> 0.030708326 | I15: =-'cloudy two 10 one 50'!AJ8 -> 0.028166838 | J15: =-'cloudy two 10 one 50'!AK8 -> 0.035673171 | K15: =AVERAGE(B15,E15,H15) -> 0.030685073 | L15: =AVERAGE(C15,F15,I15) -> 0.028145626 | M15: =AVERAGE(D15,G15,J15) -> 0.035647448 | O15: 7 | P15: =-'very sunny one 100'!AI8 -> 0.043737253 | Q15: =-'very sunny one 100'!AJ8 -> 0.016911496 | R15: =-'very sunny one 100'!AK8 -> 0.010548357 | S15: =-'cloudy one 100'!AI8 -> 0.043737253 | T15: =-'cloudy one 100'!AJ8 -> 0.016911496 | U15: =-'cloudy one 100'!AK8 -> 0.010548357 | V15: =AVERAGE(P15,S15) -> 0.043737253 | W15: =AVERAGE(Q15,T15) -> 0.016911496 | X15: =AVERAGE(R15,U15) -> 0.010548357 | Z15: 7 | AA15: =-'very sunny all 10'!AI8 -> 0.010531146 | AB15: =-'very sunny all 10'!AJ8 -> 0.019672826 | AC15: =-'very sunny all 10'!AK8 -> 0.030259756 | AD15: =-'cloudy all 10'!AI8 -> 0.010546226 | AE15: =-'cloudy all 10'!AJ8 -> 0.019713002 | AF15: =-'cloudy all 10'!AK8 -> 0.030321936 | AG15: =AVERAGE(AA15,AD15) -> 0.010538686 | AH15: =AVERAGE(AB15,AE15) -> 0.019692914 | AI15: =AVERAGE(AC15,AF15) -> 0.030290846 | AJ15: =AVERAGE(AG15:AI15) -> 0.020174149 | AK15: =SUM(AG15:AI15) -> 0.060522446
A16: 8 | B16: =-'Moderate sunny two 10 one 50'!AI9 -> 0.032217711 | C16: =-'Moderate sunny two 10 one 50'!AJ9 -> 0.028787394 | D16: =-'Moderate sunny two 10 one 50'!AK9 -> 0.036090435 | E16: =-'Very sunny two 10 one 50'!AI9 -> 0.031276062 | F16: =-'Very sunny two 10 one 50'!AJ9 -> 0.027929146 | G16: =-'Very sunny two 10 one 50'!AK9 -> 0.035047872 | H16: =-'cloudy two 10 one 50'!AI9 -> 0.032252509 | I16: =-'cloudy two 10 one 50'!AJ9 -> 0.028819297 | J16: =-'cloudy two 10 one 50'!AK9 -> 0.036129082 | K16: =AVERAGE(B16,E16,H16) -> 0.031915427 | L16: =AVERAGE(C16,F16,I16) -> 0.028511946 | M16: =AVERAGE(D16,G16,J16) -> 0.035755796 | O16: 8 | P16: =-'very sunny one 100'!AI9 -> 0.042106302 | Q16: =-'very sunny one 100'!AJ9 -> 0.016212148 | R16: =-'very sunny one 100'!AK9 -> 0.010103872 | S16: =-'cloudy one 100'!AI9 -> 0.042106302 | T16: =-'cloudy one 100'!AJ9 -> 0.016212148 | U16: =-'cloudy one 100'!AK9 -> 0.010103872 | V16: =AVERAGE(P16,S16) -> 0.042106302 | W16: =AVERAGE(Q16,T16) -> 0.016212148 | X16: =AVERAGE(R16,U16) -> 0.010103872 | Z16: 8 | AA16: =-'very sunny all 10'!AI9 -> 0.010322019 | AB16: =-'very sunny all 10'!AJ9 -> 0.019147393 | AC16: =-'very sunny all 10'!AK9 -> 0.02949041 | AD16: =-'cloudy all 10'!AI9 -> 0.010534768 | AE16: =-'cloudy all 10'!AJ9 -> 0.019710661 | AF16: =-'cloudy all 10'!AK9 -> 0.030361638 | AG16: =AVERAGE(AA16,AD16) -> 0.010428393 | AH16: =AVERAGE(AB16,AE16) -> 0.019429027 | AI16: =AVERAGE(AC16,AF16) -> 0.029926024 | AJ16: =AVERAGE(AG16:AI16) -> 0.019927815 | AK16: =SUM(AG16:AI16) -> 0.059783445
A17: 9 | B17: =-'Moderate sunny two 10 one 50'!AI10 -> 0.032307662 | C17: =-'Moderate sunny two 10 one 50'!AJ10 -> 0.028654295 | D17: =-'Moderate sunny two 10 one 50'!AK10 -> 0.035833102 | E17: =-'Very sunny two 10 one 50'!AI10 -> 0.02900201 | F17: =-'Very sunny two 10 one 50'!AJ10 -> 0.025642772 | G17: =-'Very sunny two 10 one 50'!AK10 -> 0.032174688 | H17: =-'cloudy two 10 one 50'!AI10 -> 0.032691607 | I17: =-'cloudy two 10 one 50'!AJ10 -> 0.0290043 | J17: =-'cloudy two 10 one 50'!AK10 -> 0.036258361 | K17: =AVERAGE(B17,E17,H17) -> 0.03133376 | L17: =AVERAGE(C17,F17,I17) -> 0.027767122 | M17: =AVERAGE(D17,G17,J17) -> 0.034755384 | O17: 9 | P17: =-'very sunny one 100'!AI10 -> 0.041638311 | Q17: =-'very sunny one 100'!AJ10 -> 0.016011926 | R17: =-'very sunny one 100'!AK10 -> 0.0099773462 | S17: =-'cloudy one 100'!AI10 -> 0.041638311 | T17: =-'cloudy one 100'!AJ10 -> 0.016011785 | U17: =-'cloudy one 100'!AK10 -> 0.0099765794 | V17: =AVERAGE(P17,S17) -> 0.041638311 | W17: =AVERAGE(Q17,T17) -> 0.016011855 | X17: =AVERAGE(R17,U17) -> 0.0099769628 | Z17: 9 | AA17: =-'very sunny all 10'!AI10 -> 0.0097285026 | AB17: =-'very sunny all 10'!AJ10 -> 0.017582724 | AC17: =-'very sunny all 10'!AK10 -> 0.027083012 | AD17: =-'cloudy all 10'!AI10 -> 0.010532728 | AE17: =-'cloudy all 10'!AJ10 -> 0.019711769 | AF17: =-'cloudy all 10'!AK10 -> 0.030375633 | AG17: =AVERAGE(AA17,AD17) -> 0.010130615 | AH17: =AVERAGE(AB17,AE17) -> 0.018647246 | AI17: =AVERAGE(AC17,AF17) -> 0.028729322 | AJ17: =AVERAGE(AG17:AI17) -> 0.019169061 | AK17: =SUM(AG17:AI17) -> 0.057507184
A18: 10 | B18: =-'Moderate sunny two 10 one 50'!AI11 -> 0.03175208 | C18: =-'Moderate sunny two 10 one 50'!AJ11 -> 0.028061493 | D18: =-'Moderate sunny two 10 one 50'!AK11 -> 0.035073968 | E18: =-'Very sunny two 10 one 50'!AI11 -> 0.025477717 | F18: =-'Very sunny two 10 one 50'!AJ11 -> 0.02234992 | G18: =-'Very sunny two 10 one 50'!AK11 -> 0.02813709 | H18: =-'cloudy two 10 one 50'!AI11 -> 0.032833387 | I18: =-'cloudy two 10 one 50'!AJ11 -> 0.029047022 | J18: =-'cloudy two 10 one 50'!AK11 -> 0.036271895 | K18: =AVERAGE(B18,E18,H18) -> 0.030021061 | L18: =AVERAGE(C18,F18,I18) -> 0.026486145 | M18: =AVERAGE(D18,G18,J18) -> 0.033160984 | O18: 10 | P18: =-'very sunny one 100'!AI11 -> 0.041449342 | Q18: =-'very sunny one 100'!AJ11 -> 0.015915644 | R18: =-'very sunny one 100'!AK11 -> 0.0098978888 | S18: =-'cloudy one 100'!AI11 -> 0.041449342 | T18: =-'cloudy one 100'!AJ11 -> 0.015930985 | U18: =-'cloudy one 100'!AK11 -> 0.0099254186 | V18: =AVERAGE(P18,S18) -> 0.041449342 | W18: =AVERAGE(Q18,T18) -> 0.015923314 | X18: =AVERAGE(R18,U18) -> 0.0099116537 | Z18: 10 | AA18: =-'very sunny all 10'!AI11 -> 0.0089184892 | AB18: =-'very sunny all 10'!AJ11 -> 0.015443999 | AC18: =-'very sunny all 10'!AK11 -> 0.023782948 | AD18: =-'cloudy all 10'!AI11 -> 0.010524454 | AE18: =-'cloudy all 10'!AJ11 -> 0.019692024 | AF18: =-'cloudy all 10'!AK11 -> 0.030350082 | AG18: =AVERAGE(AA18,AD18) -> 0.0097214714 | AH18: =AVERAGE(AB18,AE18) -> 0.017568011 | AI18: =AVERAGE(AC18,AF18) -> 0.027066515 | AJ18: =AVERAGE(AG18:AI18) -> 0.018118666 | AK18: =SUM(AG18:AI18) -> 0.054355998
A19: 11 | B19: =-'Moderate sunny two 10 one 50'!AI12 -> 0.031097473 | C19: =-'Moderate sunny two 10 one 50'!AJ12 -> 0.027410437 | D19: =-'Moderate sunny two 10 one 50'!AK12 -> 0.034258324 | E19: =-'Very sunny two 10 one 50'!AI12 -> 0.021873621 | F19: =-'Very sunny two 10 one 50'!AJ12 -> 0.01902116 | G19: =-'Very sunny two 10 one 50'!AK12 -> 0.024071364 | H19: =-'cloudy two 10 one 50'!AI12 -> 0.032840765 | I19: =-'cloudy two 10 one 50'!AJ12 -> 0.028999083 | J19: =-'cloudy two 10 one 50'!AK12 -> 0.036188772 | K19: =AVERAGE(B19,E19,H19) -> 0.028603953 | L19: =AVERAGE(C19,F19,I19) -> 0.02514356 | M19: =AVERAGE(D19,G19,J19) -> 0.031506154 | O19: 11 | P19: =-'very sunny one 100'!AI12 -> 0.040571055 | Q19: =-'very sunny one 100'!AJ12 -> 0.015562024 | R19: =-'very sunny one 100'!AK12 -> 0.0096955709 | S19: =-'cloudy one 100'!AI12 -> 0.041329383 | T19: =-'cloudy one 100'!AJ12 -> 0.015879684 | U19: =-'cloudy one 100'!AK12 -> 0.0098927486 | V19: =AVERAGE(P19,S19) -> 0.040950219 | W19: =AVERAGE(Q19,T19) -> 0.015720854 | X19: =AVERAGE(R19,U19) -> 0.0097941598 | Z19: 11 | AA19: =-'very sunny all 10'!AI12 -> 0.0081045424 | AB19: =-'very sunny all 10'!AJ12 -> 0.013295124 | AC19: =-'very sunny all 10'!AK12 -> 0.020468466 | AD19: =-'cloudy all 10'!AI12 -> 0.010501203 | AE19: =-'cloudy all 10'!AJ12 -> 0.019632043 | AF19: =-'cloudy all 10'!AK12 -> 0.03026031 | AG19: =AVERAGE(AA19,AD19) -> 0.0093028727 | AH19: =AVERAGE(AB19,AE19) -> 0.016463583 | AI19: =AVERAGE(AC19,AF19) -> 0.025364388 | AJ19: =AVERAGE(AG19:AI19) -> 0.017043615 | AK19: =SUM(AG19:AI19) -> 0.051130844
A20: 12 | B20: =-'Moderate sunny two 10 one 50'!AI13 -> 0.030791634 | C20: =-'Moderate sunny two 10 one 50'!AJ13 -> 0.027076912 | D20: =-'Moderate sunny two 10 one 50'!AK13 -> 0.033828757 | E20: =-'Very sunny two 10 one 50'!AI13 -> 0.019938634 | F20: =-'Very sunny two 10 one 50'!AJ13 -> 0.017207844 | G20: =-'Very sunny two 10 one 50'!AK13 -> 0.021843733 | H20: =-'cloudy two 10 one 50'!AI13 -> 0.032848091 | I20: =-'cloudy two 10 one 50'!AJ13 -> 0.028950624 | J20: =-'cloudy two 10 one 50'!AK13 -> 0.036105714 | K20: =AVERAGE(B20,E20,H20) -> 0.027859453 | L20: =AVERAGE(C20,F20,I20) -> 0.024411793 | M20: =AVERAGE(D20,G20,J20) -> 0.030592735 | O20: 12 | P20: =-'very sunny one 100'!AI13 -> 0.036902259 | Q20: =-'very sunny one 100'!AJ13 -> 0.014022992 | R20: =-'very sunny one 100'!AK13 -> 0.0087363499 | S20: =-'cloudy one 100'!AI13 -> 0.041209105 | T20: =-'cloudy one 100'!AJ13 -> 0.015828166 | U20: =-'cloudy one 100'!AK13 -> 0.0098603635 | V20: =AVERAGE(P20,S20) -> 0.039055682 | W20: =AVERAGE(Q20,T20) -> 0.014925579 | X20: =AVERAGE(R20,U20) -> 0.0092983567 | Z20: 12 | AA20: =-'very sunny all 10'!AI13 -> 0.0076532262 | AB20: =-'very sunny all 10'!AJ13 -> 0.012105582 | AC20: =-'very sunny all 10'!AK13 -> 0.018636114 | AD20: =-'cloudy all 10'!AI13 -> 0.010477849 | AE20: =-'cloudy all 10'!AJ13 -> 0.019572112 | AF20: =-'cloudy all 10'!AK13 -> 0.030170237 | AG20: =AVERAGE(AA20,AD20) -> 0.0090655376 | AH20: =AVERAGE(AB20,AE20) -> 0.015838847 | AI20: =AVERAGE(AC20,AF20) -> 0.024403175 | AJ20: =AVERAGE(AG20:AI20) -> 0.016435853 | AK20: =SUM(AG20:AI20) -> 0.04930756
... A32: 24 | B32: =-'Moderate sunny two 10 one 50'!AI25 -> 0.029637082 | C32: =-'Moderate sunny two 10 one 50'!AJ25 -> 0.027715256 | D32: =-'Moderate sunny two 10 one 50'!AK25 -> 0.035329925 | E32: =-'Very sunny two 10 one 50'!AI25 -> 0.029637082 | F32: =-'Very sunny two 10 one 50'!AJ25 -> 0.027715256 | G32: =-'Very sunny two 10 one 50'!AK25 -> 0.035329925 | H32: =-'cloudy two 10 one 50'!AI25 -> 0.029637082 | I32: =-'cloudy two 10 one 50'!AJ25 -> 0.027715256 | J32: =-'cloudy two 10 one 50'!AK25 -> 0.035329925 | K32: =AVERAGE(B32,E32,H32) -> 0.029637082 | L32: =AVERAGE(C32,F32,I32) -> 0.027715256 | M32: =AVERAGE(D32,G32,J32) -> 0.035329925 | O32: 24 | P32: =-'very sunny one 100'!AI25 -> 0.045845995 | Q32: =-'very sunny one 100'!AJ25 -> 0.017819539 | R32: =-'very sunny one 100'!AK25 -> 0.011126703 | S32: =-'cloudy one 100'!AI25 -> 0.045845995 | T32: =-'cloudy one 100'!AJ25 -> 0.017819539 | U32: =-'cloudy one 100'!AK25 -> 0.011126703 | V32: =AVERAGE(P32,S32) -> 0.045845995 | W32: =AVERAGE(Q32,T32) -> 0.017819539 | X32: =AVERAGE(R32,U32) -> 0.011126703 | Z32: 24 | AA32: =-'very sunny all 10'!AI25 -> 0.010560056 | AB32: =-'very sunny all 10'!AJ25 -> 0.019708435 | AC32: =-'very sunny all 10'!AK25 -> 0.030255897 | AD32: =-'cloudy all 10'!AI25 -> 0.010560056 | AE32: =-'cloudy all 10'!AJ25 -> 0.019708435 | AF32: =-'cloudy all 10'!AK25 -> 0.030255897 | AG32: =AVERAGE(AA32,AD32) -> 0.010560056 | AH32: =AVERAGE(AB32,AE32) -> 0.019708435 | AI32: =AVERAGE(AC32,AF32) -> 0.030255897 | AJ32: =AVERAGE(AG32:AI32) -> 0.020174796 | AK32: =SUM(AG32:AI32) -> 0.060524389
A54: hour | B54: Price (cents/kWh) - TOU | C54: Load % of Max | D54: Avg % Reduction | E54: $ Saved
A55: 1 | B55: 9.8 | C55: 0.7716
A56: 2 | B56: 9.8 | C56: 0.7517
A57: 3 | B57: 9.8 | C57: 0.7407
A58: 4 | B58: 9.8 | C58: 0.7398
A59: 5 | B59: 9.8 | C59: 0.7563
A60: 6 | B60: 9.8 | C60: 0.7986
A61: 7 | B61: 9.8 | C61: 0.8626
A62: 8 | B62: 20.3 | C62: 0.9059
A63: 9 | B63: 20.3 | C63: 0.9181
A64: 10 | B64: 20.3 | C64: 0.923
A65: 11 | B65: 20.3 | C65: 0.9261
A66: 12 | B66: 15.7 | C66: 0.9292
... A68: 14 | B68: 15.7 | C68: 0.9338
A69: 15 | B69: 15.7 | C69: 0.9404 | N69: Electricity rates | Ontario Energy Board
A70: 16 | B70: 15.7 | C70: 0.9594
A71: 17 | B71: 15.7 | C71: 0.9883
A72: 18 | B72: 20.3 | C72: 1
A73: 19 | B73: 20.3 | C73: 0.9966
A74: 20 | B74: 9.8 | C74: 0.9857
A75: 21 | B75: 9.8 | C75: 0.962
...

Sheet Moderate sunny two 10 one 50
A1: hour | B1: load 4 MW | C1: load 4 Mvar | D1: load 9 MW | E1: load 9 Mvar | F1: load 14 MW | G1: load 14 Mvar | H1: sun rating | I1: Q limit 4 | J1: Q limit 914 | K1: Bus 4 pu | L1: Bus 4 angle | M1: Bus 9 pu | N1: Bus 9 angle | O1: Bus 14 pu | P1: Bus 14 angle | Q1: load 4 MW | R1: load 4 Mvar | S1: load 9 MW | T1: load 9 Mvar | U1: load 14 MW | V1: load 14 Mvar | W1: Bus 4 pu | X1: Bus 4 angle | Y1: Bus 9 pu | Z1: Bus 9 angle | AA1: Bus 14 pu | AB1: Bus 14 angle | AC1: Qgen 4 | AD1: Qgen 9 | AE1: Qgen 14 | AF1: Load 4 MW reduction in P | AG1: Load 9 MW reduction in P | AH1: Load 14 MW reduction in P | AI1: Load 4 % reduction in P | AJ1: % Load 9 reduction in P | AK1: Load 14 % reduction in P
A2: 1 | B2: 36.882481 | C2: -3.0092399 | D2: 22.762199 | E2: 12.808559 | F2: 11.49684 | G2: 3.858 | H2: moderate sun | I2: 52.632 | J2: 10.526 | K2: 1.0149742 | L2: -7.7147192 | M2: 1.0441545 | N2: -11.394707 | O2: 1.0263809 | P2: 1.0263809 | Q2: 35.790188 | R2: -2.7766979 | S2: 22.131498 | T2: 11.614344 | U2: 11.091075 | V2: 3.387799 | W2: 0.98796874 | X2: -7.2451292 | Y2: 1.0167515 | Z2: -10.861735 | AA2: 0.99202788 | AB2: -11.42353 | AC2: -52.631996 | AD2: -10.526 | AE2: -10.526 | AF2: =Q2-B2 -> -1.0922928 | AG2: =S2-D2 -> -0.63070107 | AH2: =U2-F2 -> -0.40576458 | AI2: =AF2/B2 -> -0.029615491 | AJ2: =AG2/D2 -> -0.027708266 | AK2: =AH2/F2 -> -0.035293576
A3: 2 | B3: 35.931259 | C3: -2.9316299 | D3: 22.17515 | E3: 12.47822 | F3: 11.20033 | G3: 3.7585001 | H3: moderate sun | I3: 52.632 | J3: 10.526 | K3: 1.0156829 | L3: -7.4793466 | M3: 1.0451025 | N3: -11.065068 | O3: 1.0275118 | P3: 1.0275118 | Q3: 34.868198 | R3: -2.7056062 | S3: 21.560978 | T3: 11.317028 | U3: 10.805334 | V3: 3.3016536 | W3: 0.98870355 | X3: -7.0089468 | Y3: 1.0176876 | Z3: -10.529502 | AA3: 0.99314934 | AB3: -11.064595 | AC3: -52.631996 | AD3: -10.526 | AE3: -10.526 | AF3: =Q3-B3 -> -1.0630608 | AG3: =S3-D3 -> -0.61417198 | AH3: =U3-F3 -> -0.39499569 | AI3: =AF3/B3 -> -0.029585959 | AJ3: =AG3/D3 -> -0.027696407 | AK3: =AH3/F3 -> -0.035266434
A4: 3 | B4: 35.40546 | C4: -2.88873 | D4: 21.850651 | E4: 12.29562 | F4: 11.03643 | G4: 3.7035 | H4: moderate sun | I4: 52.632 | J4: 10.526 | K4: 1.0159664 | L4: -7.3492913 | M4: 1.0455785 | N4: -10.883109 | O4: 1.0281059 | P4: 1.0281059 | Q4: 34.362007 | R4: -2.6670759 | S4: 21.24649 | T4: 11.15419 | U4: 10.647655 | V4: 3.2542925 | W4: 0.98910278 | X4: -6.8790247 | Y4: 1.0181983 | Z4: -10.34671 | AA4: 0.99376345 | AB4: -10.867112 | AC4: -52.631996 | AD4: -10.526 | AE4: -10.526 | AF4: =Q4-B4 -> -1.0434532 | AG4: =S4-D4 -> -0.60416031 | AH4: =U4-F4 -> -0.38877487 | AI4: =AF4/B4 -> -0.029471534 | AJ4: =AG4/D4 -> -0.027649534 | AK4: =AH4/F4 -> -0.035226505
A5: 4 | B5: 35.362438 | C5: -2.8852201 | D5: 21.8241 | E5: 12.28068 | F5: 11.02302 | G5: 3.6989999 | H5: moderate sun | I5: 52.632 | J5: 10.526 | K5: 1.0159894 | L5: -7.3386567 | M5: 1.0456173 | N5: -10.86823 | O5: 1.0281545 | P5: 1.0281545 | Q5: 34.32058 | R5: -2.6639221 | S5: 21.220758 | T5: 11.140867 | U5: 10.634752 | V5: 3.2504156 | W5: 0.98913532 | X5: -6.8684037 | Y5: 1.01824 | Z5: -10.331767 | AA5: 0.99381363 | AB5: -10.850966 | AC5: -52.631996 | AD5: -10.526 | AE5: -10.526 | AF5: =Q5-B5 -> -1.0418587 | AG5: =S5-D5 -> -0.60334206 | AH5: =U5-F5 -> -0.38826752 | AI5: =AF5/B5 -> -0.029462297 | AJ5: =AG5/D5 -> -0.027645678 | AK5: =AH5/F5 -> -0.035223335
A6: 5 | B6: 36.151138 | C6: -2.9495699 | D6: 22.31085 | E6: 12.55458 | F6: 11.26887 | G6: 3.7815001 | H6: moderate sun | I6: 52.632 | J6: 10.526 | K6: 1.0155329 | L6: -7.5337295 | M6: 1.0448896 | N6: -11.141213 | O6: 1.0272543 | P6: 1.0272543 | Q6: 35.080887 | R6: -2.7219436 | S6: 21.692745 | T6: 11.38557 | U6: 10.871354 | V6: 3.3215382 | W6: 0.98853493 | X6: -7.0634351 | Y6: 1.0174723 | Z6: -10.60615 | AA6: 0.99289107 | AB6: -11.1474 | AC6: -52.631996 | AD6: -10.526 | AE6: -10.526 | AF6: =Q6-B6 -> -1.0702515 | AG6: =S6-D6 -> -0.61810493 | AH6: =U6-F6 -> -0.39751625 | AI6: =AF6/B6 -> -0.029604917 | AJ6: =AG6/D6 -> -0.02770423 | AK6: =AH6/F6 -> -0.035275608
A7: 6 | B7: 38.17308 | C7: -3.1145401 | D7: 23.558701 | E7: 13.25676 | F7: 11.89914 | G7: 3.993 | H7: moderate sun | I7: 52.632 | J7: 10.526 | K7: 1.013973 | L7: -8.0353659 | M7: 1.0428456 | N7: -11.843828 | O7: 1.0248293 | P7: 1.0248293 | Q7: 37.041901 | R7: -2.8732991 | S7: 22.905796 | T7: 12.017941 | U7: 11.478827 | V7: 3.5046499 | W7: 0.98695582 | X7: -7.5668166 | Y7: 1.0154697 | Z7: -11.314161 | AA7: 0.99049699 | AB7: -11.912297 | AC7: -52.631996 | AD7: -10.526 | AE7: -10.526 | AF7: =Q7-B7 -> -1.1311798 | AG7: =S7-D7 -> -0.65290451 | AH7: =U7-F7 -> -0.42031288 | AI7: =AF7/B7 -> -0.029632919 | AJ7: =AG7/D7 -> -0.027713944 | AK7: =AH7/F7 -> -0.035322962
A8: 7 | B8: 41.232281 | C8: -3.3641403 | D8: 25.446697 | E8: 14.31916 | F8: 12.85274 | G8: 4.3130002 | H8: moderate sun | I8: 52.632 | J8: 10.526 | K8: 1.0115343 | L8: -8.8007074 | M8: 1.0396942 | N8: -12.915614 | O8: 1.0211114 | P8: 1.0211114 | Q8: 39.966106 | R8: -3.0919499 | S8: 24.729944 | T8: 12.952592 | U8: 12.394242 | V8: 3.7769239 | W8: 0.98342872 | X8: -8.3245732 | Y8: 1.0119501 | Z8: -12.385776 | AA8: 0.98655784 | AB8: -13.073771 | AC8: -52.631996 | AD8: -10.526 | AE8: -10.526 | AF8: =Q8-B8 -> -1.2661743 | AG8: =S8-D8 -> -0.71675301 | AH8: =U8-F8 -> -0.458498 | AI8: =AF8/B8 -> -0.030708326 | AJ8: =AG8/D8 -> -0.028166838 | AK8: =AH8/F8 -> -0.035673171
A9: 8 | B9: 43.302021 | C9: -3.5330102 | D9: 26.724049 | E9: 15.03794 | F9: 13.49791 | G9: 4.5295 | H9: moderate sun | I9: 52.579368 | J9: 10.515474 | K9: 1.0098293 | L9: -9.3230657 | M9: 1.0375211 | N9: -13.646989 | O9: 1.0185617 | P9: 1.0185617 | Q9: 41.906929 | R9: -3.2307611 | S9: 25.954733 | T9: 13.56638 | U9: 13.010764 | V9: 3.9574754 | W9: 0.98018587 | X9: -8.8349633 | Y9: 1.0092212 | Z9: -13.112211 | AA9: 0.98368639 | AB9: -13.864268 | AC9: -52.579369 | AD9: -10.515474 | AE9: -10.515474 | AF9: =Q9-B9 -> -1.395092 | AG9: =S9-D9 -> -0.76931572 | AH9: =U9-F9 -> -0.48714542 | AI9: =AF9/B9 -> -0.032217711 | AJ9: =AG9/D9 -> -0.028787394 | AK9: =AH9/F9 -> -0.036090435
A10: 9 | B10: 43.885181 | C10: -3.58059 | D10: 27.083952 | E10: 15.24046 | F10: 13.67969 | G10: 4.5904999 | H10: moderate sun | I10: 52.053048 | J10: 10.410214 | K10: 1.0093408 | L10: -9.4709325 | M10: 1.0369025 | N10: -13.854004 | O10: 1.0178381 | P10: 1.0178381 | Q10: 42.467354 | R10: -3.2730744 | S10: 26.30788 | T10: 13.754396 | U10: 13.189505 | V10: 4.0141029 | W10: 0.97960824 | X10: -8.9847647 | Y10: 1.0087496 | Z10: -13.323572 | AA10: 0.9832353 | AB10: -14.096477 | AC10: -52.053047 | AD10: -10.410214 | AE10: -10.410214 | AF10: =Q10-B10 -> -1.4178276 | AG10: =S10-D10 -> -0.77607155 | AH10: =U10-F10 -> -0.49018574 | AI10: =AF10/B10 -> -0.032307662 | AJ10: =AG10/D10 -> -0.028654295 | AK10: =AH10/F10 -> -0.035833102
A11: 10 | B11: 44.1194 | C11: -3.5997 | D11: 27.228502 | E11: 15.3218 | F11: 13.752701 | G11: 4.6149998 | H11: moderate sun | I11: 50.947776 | J11: 10.189168 | K11: 1.0091435 | L11: -9.5304089 | M11: 1.0366534 | N11: -13.937267 | O11: 1.017547 | P11: 1.017547 | Q11: 42.718517 | R11: -3.2962844 | S11: 26.46443 | T11: 13.857748 | U11: 13.270339 | V11: 4.0473213 | W11: 0.97998255 | X11: -9.0539853 | Y11: 1.0090901 | Z11: -13.418095 | AA11: 0.9836877 | AB11: -14.204071 | AC11: -50.947781 | AD11: -10.189168 | AE11: -10.189168 | AF11: =Q11-B11 -> -1.4008827 | AG11: =S11-D11 -> -0.76407242 | AH11: =U11-F11 -> -0.48236179 | AI11: =AF11/B11 -> -0.03175208 | AJ11: =AG11/D11 -> -0.028061493 | AK11: =AH11/F11 -> -0.035073968
A12: 11 | B12: 44.267578 | C12: -3.6117899 | D12: 27.31995 | E12: 15.37326 | F12: 13.798889 | G12: 4.6304998 | H12: moderate sun | I12: 49.789872 | J12: 9.957596 | K12: 1.0090184 | L12: -9.568062 | M12: 1.0364957 | N12: -13.989979 | O12: 1.0173626 | P12: 1.0173626 | Q12: 42.890968 | R12: -3.3141997 | S12: 26.571098 | T12: 13.937601 | U12: 13.326162 | V12: 4.0737824 | W12: 0.98052967 | X12: -9.1023934 | Y12: 1.0095767 | Z12: -13.482793 | AA12: 0.98429775 | AB12: -14.279436 | AC12: -49.789871 | AD12: -9.9575958 | AE12: -9.9575958 | AF12: =Q12-B12 -> -1.3766098 | AG12: =S12-D12 -> -0.74885178 | AH12: =U12-F12 -> -0.47272682 | AI12: =AF12/B12 -> -0.031097473 | AJ12: =AG12/D12 -> -0.027410437 | AK12: =AH12/F12 -> -0.034258324
A13: 12 | B13: 44.41576 | C13: -3.6238801 | D13: 27.411402 | E13: 15.42472 | F13: 13.84508 | G13: 4.6459999 | H13: moderate sun | I13: 49.158288 | J13: 9.831284 | K13: 1.008893 | L13: -9.6057365 | M13: 1.0363375 | N13: -14.04272 | O13: 1.0171781 | P13: 1.0171781 | Q13: 43.048126 | R13: -3.3284705 | S13: 26.669186 | T13: 14.001208 | U13: 13.376719 | V13: 4.0941396 | W13: 0.98071861 | X13: -9.14555 | Y13: 1.0097502 | Z13: -13.541923 | AA13: 0.98453414 | AB13: -14.346476 | AC13: -49.158287 | AD13: -9.8312836 | AE13: -9.8312836 | AF13: =Q13-B13 -> -1.3676338 | AG13: =S13-D13 -> -0.74221611 | AH13: =U13-F13 -> -0.46836185 | AI13: =AF13/B13 -> -0.030791634 | AJ13: =AG13/D13 -> -0.027076912 | AK13: =AH13/F13 -> -0.033828757
... A25: 24 | B25: 38.464661 | C25: -3.1383297 | D25: 23.738649 | E25: 13.358019 | F25: 11.99003 | G25: 4.0235 | H25: moderate sun | I25: 52.632 | J25: 10.526 | K25: 1.0137447 | L25: -8.1079776 | M25: 1.0425483 | N25: -11.945523 | O25: 1.0244775 | P25: 1.0244775 | Q25: 37.32468 | R25: -2.8951139 | S25: 23.080727 | T25: 12.109091 | U25: 11.566423 | V25: 3.5310276 | W25: 0.98672456 | X25: -7.6396862 | Y25: 1.0151784 | Z25: -11.416639 | AA25: 0.99014974 | AB25: -12.023011 | AC25: -52.631996 | AD25: -10.526 | AE25: -10.526 | AF25: =Q25-B25 -> -1.1399803 | AG25: =S25-D25 -> -0.65792274 | AH25: =U25-F25 -> -0.42360687 | AI25: =AF25/B25 -> -0.029637082 | AJ25: =AG25/D25 -> -0.027715256 | AK25: =AH25/F25 -> -0.035329925

Sheet Very sunny two 10 one 50
A1: hour | B1: load 4 MW | C1: load 4 Mvar | D1: load 9 MW | E1: load 9 Mvar | F1: load 14 MW | G1: load 14 Mvar | H1: sun rating | I1: Q limit 4 | J1: Q limit 914 | K1: Bus 4 pu | L1: Bus 4 angle | M1: Bus 9 pu | N1: Bus 9 angle | O1: Bus 14 pu | P1: Bus 14 angle | Q1: load 4 MW | R1: load 4 Mvar | S1: load 9 MW | T1: load 9 Mvar | U1: load 14 MW | V1: load 14 Mvar | W1: Bus 4 pu | X1: Bus 4 angle | Y1: Bus 9 pu | Z1: Bus 9 angle | AA1: Bus 14 pu | AB1: Bus 14 angle | AC1: Qgen 4 | AD1: Qgen 9 | AE1: Qgen 14 | AF1: Load 4 MW reduction in P | AG1: Load 9 MW reduction in P | AH1: Load 14 MW reduction in P | AI1: Load 4 % reduction in P | AJ1: % Load 9 reduction in P | AK1: Load 14 % reduction in P
A2: 1 | B2: 36.882481 | C2: -3.0092399 | D2: 22.762199 | E2: 12.808559 | F2: 11.49684 | G2: 3.858 | H2: very sunny | I2: 52.632 | J2: 10.526 | K2: 1.0149742 | L2: -7.7147192 | M2: 1.0441545 | N2: -11.394707 | O2: 1.0263809 | P2: 1.0263809 | Q2: 35.790188 | R2: -2.7766979 | S2: 22.131498 | T2: 11.614344 | U2: 11.091075 | V2: 3.387799 | W2: 0.98796874 | X2: -7.2451292 | Y2: 1.0167515 | Z2: -10.861735 | AA2: 0.99202788 | AB2: -11.42353 | AC2: -52.631996 | AD2: -10.526 | AE2: -10.526 | AF2: =Q2-B2 -> -1.0922928 | AG2: =S2-D2 -> -0.63070107 | AH2: =U2-F2 -> -0.40576458 | AI2: =AF2/B2 -> -0.029615491 | AJ2: =AG2/D2 -> -0.027708266 | AK2: =AH2/F2 -> -0.035293576
A3: 2 | B3: 35.931259 | C3: -2.9316299 | D3: 22.17515 | E3: 12.47822 | F3: 11.20033 | G3: 3.7585001 | H3: very sunny | I3: 52.632 | J3: 10.526 | K3: 1.0156829 | L3: -7.4793466 | M3: 1.0451025 | N3: -11.065068 | O3: 1.0275118 | P3: 1.0275118 | Q3: 34.868198 | R3: -2.7056062 | S3: 21.560978 | T3: 11.317028 | U3: 10.805334 | V3: 3.3016536 | W3: 0.98870355 | X3: -7.0089468 | Y3: 1.0176876 | Z3: -10.529502 | AA3: 0.99314934 | AB3: -11.064595 | AC3: -52.631996 | AD3: -10.526 | AE3: -10.526 | AF3: =Q3-B3 -> -1.0630608 | AG3: =S3-D3 -> -0.61417198 | AH3: =U3-F3 -> -0.39499569 | AI3: =AF3/B3 -> -0.029585959 | AJ3: =AG3/D3 -> -0.027696407 | AK3: =AH3/F3 -> -0.035266434
A4: 3 | B4: 35.40546 | C4: -2.88873 | D4: 21.850651 | E4: 12.29562 | F4: 11.03643 | G4: 3.7035 | H4: very sunny | I4: 52.632 | J4: 10.526 | K4: 1.0159664 | L4: -7.3492913 | M4: 1.0455785 | N4: -10.883109 | O4: 1.0281059 | P4: 1.0281059 | Q4: 34.362007 | R4: -2.6670759 | S4: 21.24649 | T4: 11.15419 | U4: 10.647655 | V4: 3.2542925 | W4: 0.98910278 | X4: -6.8790247 | Y4: 1.0181983 | Z4: -10.34671 | AA4: 0.99376345 | AB4: -10.867112 | AC4: -52.631996 | AD4: -10.526 | AE4: -10.526 | AF4: =Q4-B4 -> -1.0434532 | AG4: =S4-D4 -> -0.60416031 | AH4: =U4-F4 -> -0.38877487 | AI4: =AF4/B4 -> -0.029471534 | AJ4: =AG4/D4 -> -0.027649534 | AK4: =AH4/F4 -> -0.035226505
A5: 4 | B5: 35.362438 | C5: -2.8852201 | D5: 21.8241 | E5: 12.28068 | F5: 11.02302 | G5: 3.6989999 | H5: very sunny | I5: 52.632 | J5: 10.526 | K5: 1.0159894 | L5: -7.3386567 | M5: 1.0456173 | N5: -10.86823 | O5: 1.0281545 | P5: 1.0281545 | Q5: 34.32058 | R5: -2.6639221 | S5: 21.220758 | T5: 11.140867 | U5: 10.634752 | V5: 3.2504156 | W5: 0.98913532 | X5: -6.8684037 | Y5: 1.01824 | Z5: -10.331767 | AA5: 0.99381363 | AB5: -10.850966 | AC5: -52.631996 | AD5: -10.526 | AE5: -10.526 | AF5: =Q5-B5 -> -1.0418587 | AG5: =S5-D5 -> -0.60334206 | AH5: =U5-F5 -> -0.38826752 | AI5: =AF5/B5 -> -0.029462297 | AJ5: =AG5/D5 -> -0.027645678 | AK5: =AH5/F5 -> -0.035223335
A6: 5 | B6: 36.151138 | C6: -2.9495699 | D6: 22.31085 | E6: 12.55458 | F6: 11.26887 | G6: 3.7815001 | H6: very sunny | I6: 52.632 | J6: 10.526 | K6: 1.0155329 | L6: -7.5337295 | M6: 1.0448896 | N6: -11.141213 | O6: 1.0272543 | P6: 1.0272543 | Q6: 35.080887 | R6: -2.7219436 | S6: 21.692745 | T6: 11.38557 | U6: 10.871354 | V6: 3.3215382 | W6: 0.98853493 | X6: -7.0634351 | Y6: 1.0174723 | Z6: -10.60615 | AA6: 0.99289107 | AB6: -11.1474 | AC6: -52.631996 | AD6: -10.526 | AE6: -10.526 | AF6: =Q6-B6 -> -1.0702515 | AG6: =S6-D6 -> -0.61810493 | AH6: =U6-F6 -> -0.39751625 | AI6: =AF6/B6 -> -0.029604917 | AJ6: =AG6/D6 -> -0.02770423 | AK6: =AH6/F6 -> -0.035275608
A7: 6 | B7: 38.17308 | C7: -3.1145401 | D7: 23.558701 | E7: 13.25676 | F7: 11.89914 | G7: 3.993 | H7: very sunny | I7: 52.632 | J7: 10.526 | K7: 1.013973 | L7: -8.0353659 | M7: 1.0428456 | N7: -11.843828 | O7: 1.0248293 | P7: 1.0248293 | Q7: 37.041901 | R7: -2.8732991 | S7: 22.905796 | T7: 12.017941 | U7: 11.478827 | V7: 3.5046499 | W7: 0.98695582 | X7: -7.5668166 | Y7: 1.0154697 | Z7: -11.314161 | AA7: 0.99049699 | AB7: -11.912297 | AC7: -52.631996 | AD7: -10.526 | AE7: -10.526 | AF7: =Q7-B7 -> -1.1311798 | AG7: =S7-D7 -> -0.65290451 | AH7: =U7-F7 -> -0.42031288 | AI7: =AF7/B7 -> -0.029632919 | AJ7: =AG7/D7 -> -0.027713944 | AK7: =AH7/F7 -> -0.035322962
A8: 7 | B8: 41.232281 | C8: -3.3641403 | D8: 25.446697 | E8: 14.31916 | F8: 12.85274 | G8: 4.3130002 | H8: very sunny | I8: 52.526736 | J8: 10.504948 | K8: 1.0115343 | L8: -8.8007074 | M8: 1.0396942 | N8: -12.915614 | O8: 1.0211114 | P8: 1.0211114 | Q8: 39.968983 | R8: -3.0926328 | S8: 24.731564 | T8: 12.95564 | U8: 12.395234 | V8: 3.7780662 | W8: 0.98350024 | X8: -8.3256387 | Y8: 1.0120128 | Z8: -12.386923 | AA8: 0.98663276 | AB8: -13.075471 | AC8: -52.526737 | AD8: -10.504948 | AE8: -10.504948 | AF8: =Q8-B8 -> -1.263298 | AG8: =S8-D8 -> -0.71513367 | AH8: =U8-F8 -> -0.45750618 | AI8: =AF8/B8 -> -0.030638568 | AJ8: =AG8/D8 -> -0.028103202 | AK8: =AH8/F8 -> -0.035596003
A9: 8 | B9: 43.302021 | C9: -3.5330102 | D9: 26.724049 | E9: 15.03794 | F9: 13.49791 | G9: 4.5295 | H9: very sunny | I9: 51.158304 | J9: 10.231272 | K9: 1.0098293 | L9: -9.3230657 | M9: 1.0375211 | N9: -13.646989 | O9: 1.0185617 | P9: 1.0185617 | Q9: 41.947704 | R9: -3.2404706 | S9: 25.977669 | T9: 13.609727 | U9: 13.024837 | V9: 3.9737489 | W9: 0.98115206 | X9: -8.8492393 | Y9: 1.0100662 | Z9: -13.127408 | AA9: 0.98469561 | AB9: -13.886926 | AC9: -51.158302 | AD9: -10.231272 | AE9: -10.231272 | AF9: =Q9-B9 -> -1.3543167 | AG9: =S9-D9 -> -0.74637985 | AH9: =U9-F9 -> -0.47307301 | AI9: =AF9/B9 -> -0.031276062 | AJ9: =AG9/D9 -> -0.027929146 | AK9: =AH9/F9 -> -0.035047872
A10: 9 | B10: 43.885181 | C10: -3.58059 | D10: 27.083952 | E10: 15.24046 | F10: 13.67969 | G10: 4.5904999 | H10: very sunny | I10: 47.053008 | J10: 9.410244 | K10: 1.0093408 | L10: -9.4709325 | M10: 1.0369025 | N10: -13.854004 | O10: 1.0178381 | P10: 1.0178381 | Q10: 42.612423 | R10: -3.3076622 | S10: 26.389444 | T10: 13.908858 | U10: 13.239551 | V10: 4.0721307 | W10: 0.9829973 | X10: -9.0349017 | Y10: 1.0117123 | Z10: -13.376888 | AA10: 0.98677379 | AB10: -14.175948 | AC10: -47.053009 | AD10: -9.410244 | AE10: -9.410244 | AF10: =Q10-B10 -> -1.2727585 | AG10: =S10-D10 -> -0.6945076 | AH10: =U10-F10 -> -0.44013977 | AI10: =AF10/B10 -> -0.02900201 | AJ10: =AG10/D10 -> -0.025642772 | AK10: =AH10/F10 -> -0.032174688
A11: 10 | B11: 44.1194 | C11: -3.5997 | D11: 27.228502 | E11: 15.3218 | F11: 13.752701 | G11: 4.6149998 | H11: very sunny | I11: 41.421384 | J11: 8.283962 | K11: 1.0091453 | L11: -9.5303457 | M11: 1.0366548 | N11: -13.937148 | O11: 1.0175489 | P11: 1.0175489 | Q11: 42.995338 | R11: -3.3623548 | S11: 26.619947 | T11: 14.15288 | U11: 13.36574 | V11: 4.1582322 | W11: 0.98640764 | X11: -9.1494688 | Y11: 1.014708 | Z11: -13.519813 | AA11: 0.99039572 | AB11: -14.355398 | AC11: -41.421383 | AD11: -8.2839622 | AE11: -8.2839622 | AF11: =Q11-B11 -> -1.1240616 | AG11: =S11-D11 -> -0.60855484 | AH11: =U11-F11 -> -0.38696098 | AI11: =AF11/B11 -> -0.025477717 | AJ11: =AG11/D11 -> -0.02234992 | AK11: =AH11/F11 -> -0.02813709
A12: 11 | B12: 44.267578 | C12: -3.6117899 | D12: 27.31995 | E12: 15.37326 | F12: 13.798889 | G12: 4.6304998 | H12: very sunny | I12: 35.737128 | J12: 7.147154 | K12: 1.0090196 | L12: -9.5680125 | M12: 1.0364966 | N12: -13.989888 | O12: 1.0173639 | P12: 1.0173639 | Q12: 43.299286 | R12: -3.4117453 | S12: 26.800293 | T12: 14.373413 | U12: 13.466731 | V12: 4.2376065 | W12: 0.98995936 | X12: -9.2432498 | Y12: 1.0178244 | Z12: -13.633193 | AA12: 0.99414307 | AB12: -14.502694 | AC12: -35.737129 | AD12: -7.1471543 | AE12: -7.1471543 | AF12: =Q12-B12 -> -0.96829224 | AG12: =S12-D12 -> -0.51965714 | AH12: =U12-F12 -> -0.33215809 | AI12: =AF12/B12 -> -0.021873621 | AJ12: =AG12/D12 -> -0.01902116 | AK12: =AH12/F12 -> -0.024071364
A13: 12 | B13: 44.41576 | C13: -3.6238801 | D13: 27.411402 | E13: 15.42472 | F13: 13.84508 | G13: 4.6459999 | H13: very sunny | I13: 32.579208 | J13: 6.515594 | K13: 1.0088938 | L13: -9.6056981 | M13: 1.0363382 | N13: -14.042655 | O13: 1.0171788 | P13: 1.0171788 | Q13: 43.53017 | R13: -3.443697 | S13: 26.939711 | T13: 14.516221 | U13: 13.542652 | V13: 4.2878108 | W13: 0.99180424 | X13: -9.3135163 | Y13: 1.0194501 | Z13: -13.721822 | AA13: 0.99611282 | AB13: -14.612153 | AC13: -32.579208 | AD13: -6.515594 | AE13: -6.515594 | AF13: =Q13-B13 -> -0.8855896 | AG13: =S13-D13 -> -0.47169113 | AH13: =U13-F13 -> -0.30242825 | AI13: =AF13/B13 -> -0.019938634 | AJ13: =AG13/D13 -> -0.017207844 | AK13: =AH13/F13 -> -0.021843733
... A25: 24 | B25: 38.464661 | C25: -3.1383297 | D25: 23.738649 | E25: 13.358019 | F25: 11.99003 | G25: 4.0235 | H25: very sunny | I25: 52.632 | J25: 10.526 | K25: 1.0137447 | L25: -8.1079776 | M25: 1.0425483 | N25: -11.945523 | O25: 1.0244775 | P25: 1.0244775 | Q25: 37.32468 | R25: -2.8951139 | S25: 23.080727 | T25: 12.109091 | U25: 11.566423 | V25: 3.5310276 | W25: 0.98672456 | X25: -7.6396862 | Y25: 1.0151784 | Z25: -11.416639 | AA25: 0.99014974 | AB25: -12.023011 | AC25: -52.631996 | AD25: -10.526 | AE25: -10.526 | AF25: =Q25-B25 -> -1.1399803 | AG25: =S25-D25 -> -0.65792274 | AH25: =U25-F25 -> -0.42360687 | AI25: =AF25/B25 -> -0.029637082 | AJ25: =AG25/D25 -> -0.027715256 | AK25: =AH25/F25 -> -0.035329925

Sheet cloudy two 10 one 50
A1: hour | B1: load 4 MW | C1: load 4 Mvar | D1: load 9 MW | E1: load 9 Mvar | F1: load 14 MW | G1: load 14 Mvar | H1: sun rating | I1: Q limit 4 | J1: Q limit 914 | K1: Bus 4 pu | L1: Bus 4 angle | M1: Bus 9 pu | N1: Bus 9 angle | O1: Bus 14 pu | P1: Bus 14 angle | Q1: load 4 MW | R1: load 4 Mvar | S1: load 9 MW | T1: load 9 Mvar | U1: load 14 MW | V1: load 14 Mvar | W1: Bus 4 pu | X1: Bus 4 angle | Y1: Bus 9 pu | Z1: Bus 9 angle | AA1: Bus 14 pu | AB1: Bus 14 angle | AC1: Qgen 4 | AD1: Qgen 9 | AE1: Qgen 14 | AF1: Load 4 MW reduction in P | AG1: Load 9 MW reduction in P | AH1: Load 14 MW reduction in P | AI1: Load 4 % reduction in P | AJ1: % Load 9 reduction in P | AK1: Load 14 % reduction in P
A2: 1 | B2: 36.882481 | C2: -3.0092399 | D2: 22.762199 | E2: 12.808559 | F2: 11.49684 | G2: 3.858 | H2: cloudy | I2: 52.632 | J2: 10.526 | K2: 1.0149742 | L2: -7.7147192 | M2: 1.0441545 | N2: -11.394707 | O2: 1.0263809 | P2: 1.0263809 | Q2: 35.790188 | R2: -2.7766979 | S2: 22.131498 | T2: 11.614344 | U2: 11.091075 | V2: 3.387799 | W2: 0.98796874 | X2: -7.2451292 | Y2: 1.0167515 | Z2: -10.861735 | AA2: 0.99202788 | AB2: -11.42353 | AC2: -52.631996 | AD2: -10.526 | AE2: -10.526 | AF2: =Q2-B2 -> -1.0922928 | AG2: =S2-D2 -> -0.63070107 | AH2: =U2-F2 -> -0.40576458 | AI2: =AF2/B2 -> -0.029615491 | AJ2: =AG2/D2 -> -0.027708266 | AK2: =AH2/F2 -> -0.035293576
A3: 2 | B3: 35.931259 | C3: -2.9316299 | D3: 22.17515 | E3: 12.47822 | F3: 11.20033 | G3: 3.7585001 | H3: cloudy | I3: 52.632 | J3: 10.526 | K3: 1.0156829 | L3: -7.4793466 | M3: 1.0451025 | N3: -11.065068 | O3: 1.0275118 | P3: 1.0275118 | Q3: 34.868198 | R3: -2.7056062 | S3: 21.560978 | T3: 11.317028 | U3: 10.805334 | V3: 3.3016536 | W3: 0.98870355 | X3: -7.0089468 | Y3: 1.0176876 | Z3: -10.529502 | AA3: 0.99314934 | AB3: -11.064595 | AC3: -52.631996 | AD3: -10.526 | AE3: -10.526 | AF3: =Q3-B3 -> -1.0630608 | AG3: =S3-D3 -> -0.61417198 | AH3: =U3-F3 -> -0.39499569 | AI3: =AF3/B3 -> -0.029585959 | AJ3: =AG3/D3 -> -0.027696407 | AK3: =AH3/F3 -> -0.035266434
A4: 3 | B4: 35.40546 | C4: -2.88873 | D4: 21.850651 | E4: 12.29562 | F4: 11.03643 | G4: 3.7035 | H4: cloudy | I4: 52.632 | J4: 10.526 | K4: 1.0159664 | L4: -7.3492913 | M4: 1.0455785 | N4: -10.883109 | O4: 1.0281059 | P4: 1.0281059 | Q4: 34.362007 | R4: -2.6670759 | S4: 21.24649 | T4: 11.15419 | U4: 10.647655 | V4: 3.2542925 | W4: 0.98910278 | X4: -6.8790247 | Y4: 1.0181983 | Z4: -10.34671 | AA4: 0.99376345 | AB4: -10.867112 | AC4: -52.631996 | AD4: -10.526 | AE4: -10.526 | AF4: =Q4-B4 -> -1.0434532 | AG4: =S4-D4 -> -0.60416031 | AH4: =U4-F4 -> -0.38877487 | AI4: =AF4/B4 -> -0.029471534 | AJ4: =AG4/D4 -> -0.027649534 | AK4: =AH4/F4 -> -0.035226505
A5: 4 | B5: 35.362438 | C5: -2.8852201 | D5: 21.8241 | E5: 12.28068 | F5: 11.02302 | G5: 3.6989999 | H5: cloudy | I5: 52.632 | J5: 10.526 | K5: 1.0159894 | L5: -7.3386567 | M5: 1.0456173 | N5: -10.86823 | O5: 1.0281545 | P5: 1.0281545 | Q5: 34.32058 | R5: -2.6639221 | S5: 21.220758 | T5: 11.140867 | U5: 10.634752 | V5: 3.2504156 | W5: 0.98913532 | X5: -6.8684037 | Y5: 1.01824 | Z5: -10.331767 | AA5: 0.99381363 | AB5: -10.850966 | AC5: -52.631996 | AD5: -10.526 | AE5: -10.526 | AF5: =Q5-B5 -> -1.0418587 | AG5: =S5-D5 -> -0.60334206 | AH5: =U5-F5 -> -0.38826752 | AI5: =AF5/B5 -> -0.029462297 | AJ5: =AG5/D5 -> -0.027645678 | AK5: =AH5/F5 -> -0.035223335
A6: 5 | B6: 36.151138 | C6: -2.9495699 | D6: 22.31085 | E6: 12.55458 | F6: 11.26887 | G6: 3.7815001 | H6: cloudy | I6: 52.632 | J6: 10.526 | K6: 1.0155329 | L6: -7.5337295 | M6: 1.0448896 | N6: -11.141213 | O6: 1.0272543 | P6: 1.0272543 | Q6: 35.080887 | R6: -2.7219436 | S6: 21.692745 | T6: 11.38557 | U6: 10.871354 | V6: 3.3215382 | W6: 0.98853493 | X6: -7.0634351 | Y6: 1.0174723 | Z6: -10.60615 | AA6: 0.99289107 | AB6: -11.1474 | AC6: -52.631996 | AD6: -10.526 | AE6: -10.526 | AF6: =Q6-B6 -> -1.0702515 | AG6: =S6-D6 -> -0.61810493 | AH6: =U6-F6 -> -0.39751625 | AI6: =AF6/B6 -> -0.029604917 | AJ6: =AG6/D6 -> -0.02770423 | AK6: =AH6/F6 -> -0.035275608
A7: 6 | B7: 38.17308 | C7: -3.1145401 | D7: 23.558701 | E7: 13.25676 | F7: 11.89914 | G7: 3.993 | H7: cloudy | I7: 52.632 | J7: 10.526 | K7: 1.013973 | L7: -8.0353659 | M7: 1.0428456 | N7: -11.843828 | O7: 1.0248293 | P7: 1.0248293 | Q7: 37.041901 | R7: -2.8732991 | S7: 22.905796 | T7: 12.017941 | U7: 11.478827 | V7: 3.5046499 | W7: 0.98695582 | X7: -7.5668166 | Y7: 1.0154697 | Z7: -11.314161 | AA7: 0.99049699 | AB7: -11.912297 | AC7: -52.631996 | AD7: -10.526 | AE7: -10.526 | AF7: =Q7-B7 -> -1.1311798 | AG7: =S7-D7 -> -0.65290451 | AH7: =U7-F7 -> -0.42031288 | AI7: =AF7/B7 -> -0.029632919 | AJ7: =AG7/D7 -> -0.027713944 | AK7: =AH7/F7 -> -0.035322962
A8: 7 | B8: 41.232281 | C8: -3.3641403 | D8: 25.446697 | E8: 14.31916 | F8: 12.85274 | G8: 4.3130002 | H8: cloudy | I8: 52.632 | J8: 10.526 | K8: 1.0115343 | L8: -8.8007074 | M8: 1.0396942 | N8: -12.915614 | O8: 1.0211114 | P8: 1.0211114 | Q8: 39.966106 | R8: -3.0919499 | S8: 24.729944 | T8: 12.952592 | U8: 12.394242 | V8: 3.7769239 | W8: 0.98342872 | X8: -8.3245732 | Y8: 1.0119501 | Z8: -12.385776 | AA8: 0.98655784 | AB8: -13.073771 | AC8: -52.631996 | AD8: -10.526 | AE8: -10.526 | AF8: =Q8-B8 -> -1.2661743 | AG8: =S8-D8 -> -0.71675301 | AH8: =U8-F8 -> -0.458498 | AI8: =AF8/B8 -> -0.030708326 | AJ8: =AG8/D8 -> -0.028166838 | AK8: =AH8/F8 -> -0.035673171
A9: 8 | B9: 43.302021 | C9: -3.5330102 | D9: 26.724049 | E9: 15.03794 | F9: 13.49791 | G9: 4.5295 | H9: cloudy | I9: 52.632 | J9: 10.526 | K9: 1.0098293 | L9: -9.3230657 | M9: 1.0375211 | N9: -13.646989 | O9: 1.0185617 | P9: 1.0185617 | Q9: 41.905422 | R9: -3.230402 | S9: 25.95388 | T9: 13.56477 | U9: 13.010242 | V9: 3.9568727 | W9: 0.9801501 | X9: -8.834434 | Y9: 1.0091898 | Z9: -13.111649 | AA9: 0.98364896 | AB9: -13.863429 | AC9: -52.631996 | AD9: -10.526 | AE9: -10.526 | AF9: =Q9-B9 -> -1.3965988 | AG9: =S9-D9 -> -0.7701683 | AH9: =U9-F9 -> -0.48766708 | AI9: =AF9/B9 -> -0.032252509 | AJ9: =AG9/D9 -> -0.028819297 | AK9: =AH9/F9 -> -0.036129082
A10: 9 | B10: 43.885181 | C10: -3.58059 | D10: 27.083952 | E10: 15.24046 | F10: 13.67969 | G10: 4.5904999 | H10: cloudy | I10: 52.632 | J10: 10.526 | K10: 1.0093408 | L10: -9.4709325 | M10: 1.0369025 | N10: -13.854004 | O10: 1.0178381 | P10: 1.0178381 | Q10: 42.450504 | R10: -3.2690599 | S10: 26.298401 | T10: 13.73647 | U10: 13.183687 | V10: 4.007369 | W10: 0.97921413 | X10: -8.9789616 | Y10: 1.0084052 | Z10: -13.317418 | AA10: 0.98282385 | AB10: -14.087282 | AC10: -52.631996 | AD10: -10.526 | AE10: -10.526 | AF10: =Q10-B10 -> -1.4346771 | AG10: =S10-D10 -> -0.78555107 | AH10: =U10-F10 -> -0.49600315 | AI10: =AF10/B10 -> -0.032691607 | AJ10: =AG10/D10 -> -0.0290043 | AK10: =AH10/F10 -> -0.036258361
A11: 10 | B11: 44.1194 | C11: -3.5997 | D11: 27.228502 | E11: 15.3218 | F11: 13.752701 | G11: 4.6149998 | H11: cloudy | I11: 52.579368 | J11: 10.515474 | K11: 1.0091435 | L11: -9.5304089 | M11: 1.0366534 | N11: -13.937267 | O11: 1.017547 | P11: 1.017547 | Q11: 42.670811 | R11: -3.2849112 | S11: 26.437595 | T11: 13.806968 | U11: 13.253864 | V11: 4.0282378 | W11: 0.9788726 | X11: -9.0376458 | Y11: 1.0081205 | Z11: -13.400777 | AA11: 0.98252916 | AB11: -14.178196 | AC11: -52.579369 | AD11: -10.515474 | AE11: -10.515474 | AF11: =Q11-B11 -> -1.4485893 | AG11: =S11-D11 -> -0.79090691 | AH11: =U11-F11 -> -0.49883652 | AI11: =AF11/B11 -> -0.032833387 | AJ11: =AG11/D11 -> -0.029047022 | AK11: =AH11/F11 -> -0.036271895
A12: 11 | B12: 44.267578 | C12: -3.6117899 | D12: 27.31995 | E12: 15.37326 | F12: 13.798889 | G12: 4.6304998 | H12: cloudy | I12: 52.421472 | J12: 10.483896 | K12: 1.0090184 | L12: -9.568062 | M12: 1.0364957 | N12: -13.989979 | O12: 1.0173626 | P12: 1.0173626 | Q12: 42.813797 | R12: -3.295799 | S12: 26.527697 | T12: 13.855433 | U12: 13.299524 | V12: 4.0429034 | W12: 0.97874093 | X12: -9.0760519 | Y12: 1.0080142 | Z12: -13.45488 | AA12: 0.98243117 | AB12: -14.237736 | AC12: -52.421467 | AD12: -10.483896 | AE12: -10.483896 | AF12: =Q12-B12 -> -1.4537811 | AG12: =S12-D12 -> -0.79225349 | AH12: =U12-F12 -> -0.49936485 | AI12: =AF12/B12 -> -0.032840765 | AJ12: =AG12/D12 -> -0.028999083 | AK12: =AH12/F12 -> -0.036188772
A13: 12 | B13: 44.41576 | C13: -3.6238801 | D13: 27.411402 | E13: 15.42472 | F13: 13.84508 | G13: 4.6459999 | H13: cloudy | I13: 52.263576 | J13: 10.452318 | K13: 1.008893 | L13: -9.6057365 | M13: 1.0363375 | N13: -14.04272 | O13: 1.0171781 | P13: 1.0171781 | Q13: 42.956787 | R13: -3.3066869 | S13: 26.617825 | T13: 13.903928 | U13: 13.345194 | V13: 4.0575752 | W13: 0.97860891 | X13: -9.1144828 | Y13: 1.0079076 | Z13: -13.509017 | AA13: 0.98233294 | AB13: -14.297312 | AC13: -52.263577 | AD13: -10.452318 | AE13: -10.452318 | AF13: =Q13-B13 -> -1.4589729 | AG13: =S13-D13 -> -0.79357719 | AH13: =U13-F13 -> -0.49988651 | AI13: =AF13/B13 -> -0.032848091 | AJ13: =AG13/D13 -> -0.028950624 | AK13: =AH13/F13 -> -0.036105714
... A25: 24 | B25: 38.464661 | C25: -3.1383297 | D25: 23.738649 | E25: 13.358019 | F25: 11.99003 | G25: 4.0235 | H25: cloudy | I25: 52.632 | J25: 10.526 | K25: 1.0137447 | L25: -8.1079776 | M25: 1.0425483 | N25: -11.945523 | O25: 1.0244775 | P25: 1.0244775 | Q25: 37.32468 | R25: -2.8951139 | S25: 23.080727 | T25: 12.109091 | U25: 11.566423 | V25: 3.5310276 | W25: 0.98672456 | X25: -7.6396862 | Y25: 1.0151784 | Z25: -11.416639 | AA25: 0.99014974 | AB25: -12.023011 | AC25: -52.631996 | AD25: -10.526 | AE25: -10.526 | AF25: =Q25-B25 -> -1.1399803 | AG25: =S25-D25 -> -0.65792274 | AH25: =U25-F25 -> -0.42360687 | AI25: =AF25/B25 -> -0.029637082 | AJ25: =AG25/D25 -> -0.027715256 | AK25: =AH25/F25 -> -0.035329925

Sheet cloudy one 100
A1: hour | B1: load 4 MW | C1: load 4 Mvar | D1: load 9 MW | E1: load 9 Mvar | F1: load 14 MW | G1: load 14 Mvar | H1: sun rating | I1: Q limit 4 | J1: Q limit 914 | K1: Bus 4 pu | L1: Bus 4 angle | M1: Bus 9 pu | N1: Bus 9 angle | O1: Bus 14 pu | P1: Bus 14 angle | Q1: load 4 MW | R1: load 4 Mvar | S1: load 9 MW | T1: load 9 Mvar | U1: load 14 MW | V1: load 14 Mvar | W1: Bus 4 pu | X1: Bus 4 angle | Y1: Bus 9 pu | Z1: Bus 9 angle | AA1: Bus 14 pu | AB1: Bus 14 angle | AC1: Qgen 4 | AD1: Qgen 9 | AE1: Qgen 14 | AF1: Load 4 MW reduction in P | AG1: Load 9 MW reduction in P | AH1: Load 14 MW reduction in P | AI1: Load 4 % reduction in P | AJ1: % Load 9 reduction in P | AK1: Load 14 % reduction in P
A2: 1 | B2: 36.882481 | C2: -3.0092399 | D2: 22.762199 | E2: 12.808559 | F2: 11.49684 | G2: 3.858 | H2: cloudy | I2: 105.263 | J2: 0 | K2: 1.0149734 | L2: -7.7147978 | M2: 1.0441538 | N2: -11.394835 | O2: 1.0263802 | P2: 1.0263802 | Q2: 35.14843 | R2: -2.6254513 | S2: 22.345486 | T2: 12.016339 | U2: 11.365592 | V2: 3.7043438 | W2: 0.97000003 | X2: -7.0226179 | Y2: 1.0260569 | Z2: -10.78303 | AA2: 1.0152819 | AB2: -11.770888 | AC2: -91.666534 | AD2: 0 | AE2: 0 | AF2: =Q2-B2 -> -1.7340508 | AG2: =S2-D2 -> -0.41671371 | AH2: =U2-F2 -> -0.13124752 | AI2: =AF2/B2 -> -0.047015567 | AJ2: =AG2/D2 -> -0.018307269 | AK2: =AH2/F2 -> -0.011415965
A3: 2 | B3: 35.931259 | C3: -2.9316299 | D3: 22.17515 | E3: 12.47822 | F3: 11.20033 | G3: 3.7585001 | H3: cloudy | I3: 105.263 | J3: 0 | K3: 1.0156829 | L3: -7.4793466 | M3: 1.0451025 | N3: -11.065068 | O3: 1.0275118 | P3: 1.0275118 | Q3: 34.217693 | R3: -2.5524857 | S3: 21.762457 | T3: 11.694921 | U3: 11.070158 | V3: 3.6064107 | W3: 0.97000003 | X3: -6.7865733 | Y3: 1.0266896 | Z3: -10.455975 | AA3: 1.0162011 | AB3: -11.419668 | AC3: -93.903259 | AD3: 0 | AE3: 0 | AF3: =Q3-B3 -> -1.7135658 | AG3: =S3-D3 -> -0.41269302 | AH3: =U3-F3 -> -0.13017178 | AI3: =AF3/B3 -> -0.047690113 | AJ3: =AG3/D3 -> -0.018610608 | AK3: =AH3/F3 -> -0.011622138
A4: 3 | B4: 35.40546 | C4: -2.88873 | D4: 21.850651 | E4: 12.29562 | F4: 11.03643 | G4: 3.7035 | H4: cloudy | I4: 105.263 | J4: 0 | K4: 1.0159664 | L4: -7.3492913 | M4: 1.0455785 | N4: -10.883109 | O4: 1.0281059 | P4: 1.0281059 | Q4: 33.707436 | R4: -2.5130703 | S4: 21.441408 | T4: 11.519491 | U4: 10.907315 | V4: 3.5528009 | W4: 0.97000003 | X4: -6.6492003 | Y4: 1.0270404 | Z4: -10.266031 | AA4: 1.0167141 | AB4: -11.216316 | AC4: -95.154984 | AD4: 0 | AE4: 0 | AF4: =Q4-B4 -> -1.6980247 | AG4: =S4-D4 -> -0.40924263 | AH4: =U4-F4 -> -0.1291151 | AI4: =AF4/B4 -> -0.047959403 | AJ4: =AG4/D4 -> -0.018729082 | AK4: =AH4/F4 -> -0.011698991
A5: 4 | B5: 35.362438 | C5: -2.8852201 | D5: 21.8241 | E5: 12.28068 | F5: 11.02302 | G5: 3.6989999 | H5: cloudy | I5: 105.263 | J5: 0 | K5: 1.0159894 | L5: -7.3386567 | M5: 1.0456173 | N5: -10.86823 | O5: 1.0281545 | P5: 1.0281545 | Q5: 33.665703 | R5: -2.5098493 | S5: 21.415144 | T5: 11.505146 | U5: 10.893991 | V5: 3.5484166 | W5: 0.96999997 | X5: -6.6379698 | Y5: 1.027069 | Z5: -10.2505 | AA5: 1.0167561 | AB5: -11.199688 | AC5: -95.257126 | AD5: 0 | AE5: 0 | AF5: =Q5-B5 -> -1.6967354 | AG5: =S5-D5 -> -0.40895653 | AH5: =U5-F5 -> -0.12902832 | AI5: =AF5/B5 -> -0.047981289 | AJ5: =AG5/D5 -> -0.018738758 | AK5: =AH5/F5 -> -0.011705351
A6: 5 | B6: 36.151138 | C6: -2.9495699 | D6: 22.31085 | E6: 12.55458 | F6: 11.26887 | G6: 3.7815001 | H6: cloudy | I6: 105.263 | J6: 0 | K6: 1.0155329 | L6: -7.5337295 | M6: 1.0448896 | N6: -11.141213 | O6: 1.0272543 | P6: 1.0272543 | Q6: 34.432243 | R6: -2.5692217 | S6: 21.897017 | T6: 11.768835 | U6: 11.138357 | V6: 3.6289408 | W6: 0.96999997 | X6: -6.844186 | Y6: 1.0265418 | Z6: -10.535604 | AA6: 1.0159856 | AB6: -11.504911 | AC6: -93.376183 | AD6: 0 | AE6: 0 | AF6: =Q6-B6 -> -1.718895 | AG6: =S6-D6 -> -0.41383362 | AH6: =U6-F6 -> -0.13051319 | AI6: =AF6/B6 -> -0.047547464 | AJ6: =AG6/D6 -> -0.018548536 | AK6: =AH6/F6 -> -0.011581746
A7: 6 | B7: 38.17308 | C7: -3.1145401 | D7: 23.558701 | E7: 13.25676 | F7: 11.89914 | G7: 3.993 | H7: cloudy | I7: 105.263 | J7: 0 | K7: 1.013973 | L7: -8.0353659 | M7: 1.0428456 | N7: -11.843828 | O7: 1.0248293 | P7: 1.0248293 | Q7: 36.414696 | R7: -2.7252252 | S7: 23.136681 | T7: 12.452659 | U7: 11.766032 | V7: 3.836735 | W7: 0.97000009 | X7: -7.382813 | Y7: 1.0251595 | Z7: -11.283076 | AA7: 1.0139699 | AB7: -12.304628 | AC7: -88.355942 | AD7: 0 | AE7: 0 | AF7: =Q7-B7 -> -1.7583847 | AG7: =S7-D7 -> -0.42201996 | AH7: =U7-F7 -> -0.13310814 | AI7: =AF7/B7 -> -0.046063474 | AJ7: =AG7/D7 -> -0.01791355 | AK7: =AH7/F7 -> -0.011186366
A8: 7 | B8: 41.232281 | C8: -3.3641403 | D8: 25.446697 | E8: 14.31916 | F8: 12.85274 | G8: 4.3130002 | H8: cloudy | I8: 105.263 | J8: 0 | K8: 1.0115343 | L8: -8.8007074 | M8: 1.0396942 | N8: -12.915614 | O8: 1.0211114 | P8: 1.0211114 | Q8: 39.428894 | R8: -2.9646065 | S8: 25.016356 | T8: 13.494703 | U8: 12.717165 | V8: 4.1527662 | W8: 0.97000003 | X8: -8.1996721 | Y8: 1.0230461 | Z8: -12.411016 | AA8: 1.0109071 | AB8: -13.51166 | AC8: -80.64476 | AD8: 0 | AE8: 0 | AF8: =Q8-B8 -> -1.8033867 | AG8: =S8-D8 -> -0.43034172 | AH8: =U8-F8 -> -0.13557529 | AI8: =AF8/B8 -> -0.043737253 | AJ8: =AG8/D8 -> -0.016911496 | AK8: =AH8/F8 -> -0.010548357
A9: 8 | B9: 43.302021 | C9: -3.5330102 | D9: 26.724049 | E9: 15.03794 | F9: 13.49791 | G9: 4.5295 | H9: cloudy | I9: 105.263 | J9: 0 | K9: 1.0098293 | L9: -9.3230657 | M9: 1.0375211 | N9: -13.646989 | O9: 1.0185617 | P9: 1.0185617 | Q9: 41.478733 | R9: -3.128983 | S9: 26.290794 | T9: 14.204733 | U9: 13.361528 | V9: 4.3675585 | W9: 0.97000003 | X9: -8.7578445 | Y9: 1.0215938 | Z9: -13.180594 | AA9: 1.0088108 | AB9: -14.335182 | AC9: -75.281982 | AD9: 0 | AE9: 0 | AF9: =Q9-B9 -> -1.823288 | AG9: =S9-D9 -> -0.43325424 | AH9: =U9-F9 -> -0.13638115 | AI9: =AF9/B9 -> -0.042106302 | AJ9: =AG9/D9 -> -0.016212148 | AK9: =AH9/F9 -> -0.010103872
A10: 9 | B10: 43.885181 | C10: -3.58059 | D10: 27.083952 | E10: 15.24046 | F10: 13.67969 | G10: 4.5904999 | H10: cloudy | I10: 105.263 | J10: 0 | K10: 1.0093408 | L10: -9.4709325 | M10: 1.0369025 | N10: -13.854004 | O10: 1.0178381 | P10: 1.0178381 | Q10: 42.057877 | R10: -3.1756647 | S10: 26.65029 | T10: 14.405553 | U10: 13.543214 | V10: 4.4282289 | W10: 0.97000003 | X10: -8.9159429 | Y10: 1.0211811 | Z10: -13.39839 | AA10: 1.0082166 | AB10: -14.568239 | AC10: -73.749321 | AD10: 0 | AE10: 0 | AF10: =Q10-B10 -> -1.8273048 | AG10: =S10-D10 -> -0.43366241 | AH10: =U10-F10 -> -0.13647652 | AI10: =AF10/B10 -> -0.041638311 | AJ10: =AG10/D10 -> -0.016011785 | AK10: =AH10/F10 -> -0.0099765794
A11: 10 | B11: 44.1194 | C11: -3.5997 | D11: 27.228502 | E11: 15.3218 | F11: 13.752701 | G11: 4.6149998 | H11: cloudy | I11: 105.15774 | J11: 0 | K11: 1.0091435 | L11: -9.5304089 | M11: 1.0366534 | N11: -13.937267 | O11: 1.017547 | P11: 1.017547 | Q11: 42.29068 | R11: -3.1944611 | S11: 26.794725 | T11: 14.486308 | U11: 13.616199 | V11: 4.4526119 | W11: 0.97000003 | X11: -8.9795439 | Y11: 1.0210149 | Z11: -13.485986 | AA11: 1.0079775 | AB11: -14.661969 | AC11: -73.13105 | AD11: 0 | AE11: 0 | AF11: =Q11-B11 -> -1.8287201 | AG11: =S11-D11 -> -0.43377686 | AH11: =U11-F11 -> -0.13650131 | AI11: =AF11/B11 -> -0.041449342 | AJ11: =AG11/D11 -> -0.015930985 | AK11: =AH11/F11 -> -0.0099254186
A12: 11 | B12: 44.267578 | C12: -3.6117899 | D12: 27.31995 | E12: 15.37326 | F12: 13.798889 | G12: 4.6304998 | H12: cloudy | I12: 104.84195 | J12: 0 | K12: 1.0090184 | L12: -9.568062 | M12: 1.0364957 | N12: -13.989979 | O12: 1.0173626 | P12: 1.0173626 | Q12: 42.438026 | R12: -3.2063651 | S12: 26.886118 | T12: 14.537424 | U12: 13.66238 | V12: 4.4680448 | W12: 0.97000003 | X12: -9.019813 | Y12: 1.0209098 | Z12: -13.541439 | AA12: 1.0078261 | AB12: -14.721308 | AC12: -72.739098 | AD12: 0 | AE12: 0 | AF12: =Q12-B12 -> -1.8295517 | AG12: =S12-D12 -> -0.43383217 | AH12: =U12-F12 -> -0.13650894 | AI12: =AF12/B12 -> -0.041329383 | AJ12: =AG12/D12 -> -0.015879684 | AK12: =AH12/F12 -> -0.0098927486
A13: 12 | B13: 44.41576 | C13: -3.6238801 | D13: 27.411402 | E13: 15.42472 | F13: 13.84508 | G13: 4.6459999 | H13: cloudy | I13: 104.52616 | J13: 0 | K13: 1.008893 | L13: -9.6057365 | M13: 1.0363375 | N13: -14.04272 | O13: 1.0171781 | P13: 1.0171781 | Q13: 42.585426 | R13: -3.2182827 | S13: 26.97753 | T13: 14.588571 | U13: 13.708563 | V13: 4.4834824 | W13: 0.97000003 | X13: -9.0601077 | Y13: 1.0208044 | Z13: -13.596923 | AA13: 1.0076746 | AB13: -14.780678 | AC13: -72.346504 | AD13: 0 | AE13: 0 | AF13: =Q13-B13 -> -1.8303337 | AG13: =S13-D13 -> -0.43387222 | AH13: =U13-F13 -> -0.13651752 | AI13: =AF13/B13 -> -0.041209105 | AJ13: =AG13/D13 -> -0.015828166 | AK13: =AH13/F13 -> -0.0098603635
